Document (globalcampus.site/namespace.stxt): Manejo de excepciones (try, except, finally)
	
	Content: 
	Header: Manejo de excepciones (try, except, finally) en Python
	
	Content:
	    
	    El manejo de excepciones en Python permite controlar los errores que pueden ocurrir durante la ejecución de un programa. Usando las estructuras ```try```, ```except```, y ```finally```, se puede gestionar de manera adecuada estos errores, asegurando que el programa pueda manejar situaciones inesperadas sin detenerse abruptamente.
	    
	Header: Estructura Básica
	
	Content:
	    
	    La estructura básica para el manejo de excepciones es la siguiente:
	    
	Code:
	    try:
	    # Código que puede producir una excepción
	    except TipoDeExcepcion:
	    # Código que se ejecuta si ocurre la excepción
	    finally:
	    # Código que se ejecuta siempre, ocurra o no una excepción
	
	
	Content:
	    
	Header: Bloque try
	
	Content:
	    
	    El bloque ```try``` contiene el código que puede producir una excepción. Si no ocurre ninguna excepción, el bloque ```except``` es ignorado y el programa continúa con la siguiente instrucción después del bloque ```try```.
	    
	    Ejemplo:
	Code:
	    try:
	    resultado = 10 / 2
	    print("El resultado es:", resultado)
	    except ZeroDivisionError:
	    print("Error: División por cero.")
	
	
	Content:
	    
	Header: Bloque except
	
	Content:
	    
	    El bloque ```except``` se ejecuta si ocurre una excepción en el bloque ```try```. Se puede especificar el tipo de excepción a capturar.
	    
	    Ejemplo:
	Code:
	    try:
	    resultado = 10 / 0
	    except ZeroDivisionError:
	    print("Error: División por cero.")
	
	
	Content:
	    
	    También se pueden capturar múltiples excepciones especificándolas en una tupla.
	Code:
	    try:
	    resultado = 10 / 0
	    except (ZeroDivisionError, TypeError):
	    print("Error: Ocurrió una excepción.")
	
	
	Content:
	    
	    Se puede capturar cualquier excepción usando un bloque ```except``` sin especificar el tipo de excepción.
	Code:
	    try:
	    resultado = 10 / 0
	    except:
	    print("Error: Ocurrió una excepción.")
	
	
	Content:
	    
	Header: Bloque else
	
	Content:
	    
	    El bloque ```else``` se ejecuta si no ocurre ninguna excepción en el bloque ```try```.
	Code:
	    try:
	    resultado = 10 / 2
	    except ZeroDivisionError:
	    print("Error: División por cero.")
	    else:
	    print("El resultado es:", resultado)
	
	
	Content:
	    
	Header: Bloque finally
	
	Content:
	    
	    El bloque ```finally``` contiene el código que se ejecuta siempre, ocurra o no una excepción. Es útil para liberar recursos o realizar tareas de limpieza.
	    
	    Ejemplo:
	Code:
	    try:
	    archivo = open("datos.txt", "r")
	    contenido = archivo.read()
	    except FileNotFoundError:
	    print("Error: Archivo no encontrado.")
	    finally:
	    archivo.close()
	
	
	Content:
	    
	Header: Lanzar Excepciones
	
	Content:
	    
	    Se pueden lanzar excepciones manualmente usando la palabra clave ```raise```.
	Code:
	    raise ValueError("Este es un error personalizado.")
	
	
	Content:
	    
	Header: Definir Excepciones Personalizadas
	
	Content:
	    
	    Se pueden definir excepciones personalizadas creando una nueva clase que herede de la clase base ```Exception```.
	Code:
	    class MiExcepcion(Exception):
	    def init(self, mensaje):
	    self.mensaje = mensaje
	    
	    try:
	    raise MiExcepcion("Ocurrió un error personalizado.")
	    except MiExcepcion as e:
	    print(e.mensaje)
	
	
	Content:
	    
	Header: Ventajas del Manejo de Excepciones
	
	Content:
	    
	    *  **Robustez**: Permite que el programa continúe ejecutándose o se cierre de manera controlada en caso de errores.
	    *  **Claridad**: Mejora la legibilidad del código al separar la lógica de manejo de errores del flujo principal del programa.
	    *  **Mantenimiento**: Facilita la identificación y corrección de errores, y permite añadir nuevas excepciones de manera sencilla.
